Workbook
Name Actual: [12]Soportes!$M$2:$M$3
Name Mes: [21]Toggle!$G$2:$G$13
Name Mes: [22]Toggle!$G$2:$G$13
Name Mes: [23]Toggle!$D$3:$D$14
Name Meses: [21]Toggle!$A$1:$A$192
Name Meses: [22]Toggle!$A$1:$A$192
Name Meses: [23]Toggle!$G$3:$G$254
Name Start_12: '[24]Variables Relevantes'!#REF!
Name Start_12: '[25]Variables Relevantes'!#REF!
Name Start_13: '[24]EDE''s'!#REF!
Name Start_13: '[25]EDE''s'!#REF!
Name Start_14: [24]CDEEE!#REF!
Name Start_14: [25]CDEEE!#REF!
Name Start_15: [24]EGEHID!#REF!
Name Start_15: [25]EGEHID!#REF!
Name Start_16: [24]ETED!#REF!
Name Start_16: [25]ETED!#REF!
Name Start_17: '[24]Anexo Res Financieros'!#REF!
Name Start_17: #REF!
Name Start_18: '[26]Anexo Res Financieros'!#REF!
Name Start_3: #REF!
Name Start_62: #REF!
Name Start_63: #REF!
Name Status: [22]Toggle!$C$3:$C$4
Name Status: [21]Toggle!$C$3:$C$4
Name Toggle: [22]Toggle!$B$3:$B$4
Name Toggle: [21]Toggle!$B$3:$B$4

Sheet Variables Relevantes
B2: Ministerio de Energía y Minas
B3: Variables Relevantes
B4: Valores según indicación
L5: 2009 | M5: 2009 | N5: 2009 | O5: 2009 | P5: 2009 | Q5: 2009 | R5: 2009 | S5: 2009 | T5: 2009 | U5: 2009 | V5: 2009 | W5: 2009 | X5: 2010 | Y5: 2010 | Z5: 2010 | AA5: 2010 | AB5: 2010 | AC5: 2010 | AD5: 2010 | AE5: 2010 | AF5: 2010 | AG5: 2010 | AH5: 2010 | AI5: 2010 | AJ5: 2011 | AK5: 2011 | AL5: 2011 | AM5: 2011 | AN5: 2011 | AO5: 2011 | AP5: 2011 | AQ5: 2011 | AR5: 2011 | AS5: 2011 | AT5: 2011 | AU5: 2011 | AV5: 2012 | AW5: 2012 | AX5: 2012 | AY5: 2012 | AZ5: 2012 | BA5: 2012 | BB5: 2012 | BC5: 2012 | BD5: 2012 | BE5: 2012 | BF5: 2012 | BG5: 2012 | BH5: 2013 | BI5: 2013 | BJ5: 2013 | BK5: 2013 | BL5: 2013 | BM5: 2013 | BN5: 2013 | BO5: 2013 | BP5: 2013 | BQ5: 2013 | BR5: 2013 | BS5: 2013 | BT5: 2014 | BU5: 2014 | BV5: 2014 | BW5: 2014 | BX5: 2014 | BY5: 2014 | BZ5: 2014
C6: Ene21-Nov21 | D6: Ene20-Nov20 | E6: Comparación 2020 - 2021 | H6: Ene19-Nov19 | I6: Comparación 2019 - 2020 | FL6: Acumulado Año
E7: D | F7: D% | I7: D | J7: D% | L7: 39814 | M7: 39845 | N7: 39873 | O7: 39904 | P7: 39934 | Q7: 39965 | R7: 39995 | S7: 40026 | T7: 40057 | U7: 40087 | V7: 40118 | W7: 40148 | X7: 40179 | Y7: 40210 | Z7: 40238 | AA7: 40269 | AB7: 40299 | AC7: 40330 | AD7: 40360 | AE7: 40391 | AF7: 40422 | AG7: 40452 | AH7: 40483 | AI7: 40513 | AJ7: 40544 | AK7: 40575 | AL7: 40603 | AM7: 40634 | AN7: 40664 | AO7: 40695 | AP7: 40725 | AQ7: 40756 | AR7: 40787 | AS7: 40817 | AT7: 40848 | AU7: 40878 | AV7: 40909 | AW7: 40940 | AX7: 40969 | AY7: 41000 | AZ7: 41030 | BA7: 41061 | BB7: 41091 | BC7: 41122 | BD7: 41153 | BE7: 41183 | BF7: 41214 | BG7: 41244 | BH7: 41275 | BI7: 41306 | BJ7: 41334 | BK7: 41365 | BL7: 41395 | BM7: 41426 | BN7: 41456 | BO7: 41487 | BP7: 41518 | BQ7: 41548 | BR7: 41579 | BS7: 41609 | BT7: 41640 | BU7: 41671 | BV7: 41699 | BW7: 41730 | BX7: 41760 | BY7: 41791 | BZ7: 41821 | CA7: 41852 | CB7: 41883 | CC7: 41913 | CD7: 41944 | CE7: 41974 | CF7: 42005 | CG7: 42036 | CH7: 42064 | CI7: 42095 | CJ7: 42125 | CK7: 42156 | CL7: 42186 | CM7: 42217 | CN7: 42248 | CO7: 42278 | CP7: 42309 | CQ7: 42339 | CR7: 42370 | CS7: 42401 | CT7: 42430 | CU7: 42461 | CV7: 42491 | CW7: 42522 | CX7: 42552 | CY7: 42583 | CZ7: 42614 | DA7: 42644 | DB7: 42675 | DC7: 42705 | DD7: 42736 | DE7: 42767 | DF7: 42795 | DG7: 42826 | DH7: 42856 | DI7: 42887 | DJ7: 42917 | DK7: 42948 | DL7: 42979 | DM7: 43009 | DN7: 43040 | DO7: 43070 | DP7: 43101 | DQ7: 43132 | DR7: 43160 | DS7: 43191 | DT7: 43221 | DU7: 43252 | DV7: 43282 | DW7: 43313 | DX7: 43344 | DY7: 43374 | DZ7: 43405 | EA7: 43435 | EB7: 43466 | EC7: 43497 | ED7: 43525 | EE7: 43556 | EF7: 43586 | EG7: 43617 | EH7: 43647 | EI7: 43678 | EJ7: 43709 | EK7: 43739 | EL7: 43770 | EM7: 43800 | EN7: 43831 | EO7: 43862 | EP7: 43891 | EQ7: 43922 | ER7: 43952 | ES7: 43983 | ET7: 44013 | EU7: 44044 | EV7: 44075 | EW7: 44105 | EX7: 44136 | EY7: 44166 | EZ7: 44197 | FA7: 44228 | FB7: 44256 | FC7: 44287 | FD7: 44317 | FE7: 44348 | FF7: 44378 | FG7: 44409 | FH7: 44440 | FI7: 44470 | FJ7: 44501 | FL7: 2009 | FM7: 2010 | FN7: 2011 | FO7: 2012 | FP7: 2013 | FQ7: 2014 | FR7: 2015 | FS7: 2016 | FT7: 2017 | FU7: 2018 | FV7: 2019 | FW7: 2020 | FX7: 2021
B8: Precios Combustibles
A9: 8 | B9: Fuel Oil # 2 (US$/BBL) | C9: 76.219469 | D9: 46.044103 | E9: 30.175366 | F9: 0.6553579 | H9: 76.474631 | I9: -30.430528 | J9: -0.39791664 | L9: 58.9014 | M9: 51.7628 | N9: 51.7713 | O9: 55.9641 | P9: 61.4095 | Q9: 73.4096 | R9: 68.1985 | S9: 78.093 | T9: 72.565 | U9: 80.807141 | V9: 82.9503 | W9: 82.070386 | X9: 85.064147 | Y9: 82.077284 | Z9: 86.686996 | AA9: 92.3491 | AB9: 84.848925 | AC9: 84.548482 | AD9: 82.5055 | AE9: 84.976214 | AF9: 87.0492 | AG9: 93.3613 | AH9: 96.12645 | AI9: 101.67704 | AJ9: 107.68002 | AK9: 114.97611 | AL9: 126.29875 | AM9: 133.5949 | AN9: 123.5946 | AO9: 124.0428 | AP9: 128.10735 | AQ9: 122.63635 | AR9: 121.9579 | AS9: 123.1108 | AT9: 127.42275 | AU9: 119.7879 | AV9: 126.71946 | AW9: 132.7872 | AX9: 134.60045 | AY9: 132.29979 | AZ9: 122.38189 | BA9: 109.8258 | BB9: 116.9128 | BC9: 127.2463 | BD9: 131.65851 | BE9: 130.21881 | BF9: 123.90294 | BG9: 123.69168 | BH9: 126.9378 | BI9: 132.35593 | BJ9: 122.42076 | BK9: 115.14739 | BL9: 114.63575 | BM9: 116.43156 | BN9: 120.60796 | BO9: 124.39885 | BP9: 123.50583 | BQ9: 122.19553 | BR9: 119.06823 | BS9: 123.3216 | BT9: 120.7294 | BU9: 120.99979 | BV9: 119.7954 | BW9: 121.1192 | BX9: 120.0848 | BY9: 120.8904 | BZ9: 117.5979 | CA9: 116.3406 | CB9: 111.0988 | CC9: 101.83959 | CD9: 93.4794 | CE9: 72.6562 | CF9: 64.76022 | CG9: 73.518458 | CH9: 68.7939 | CI9: 72.086 | CJ9: 77.48013 | CK9: 72.4437 | CL9: 64.756745 | CM9: 57.9812 | CN9: 58.2938 | CO9: 58.242927 | CP9: 54.294063 | CQ9: 43.0395 | CR9: 38.148821 | CS9: 38.08245 | CT9: 41.849564 | CU9: 46.608 | CV9: 53.7636 | CW9: 57.644236 | CX9: 51.47835 | CY9: 53.399987 | CZ9: 54.6616 | DA9: 60.1302 | DB9: 54.87006 | DC9: 61.6612 | DD9: 63.222 | DE9: 63.899 | DF9: 59.364809 | DG9: 61.130337 | DH9: 57.995891 | DI9: 53.709409 | DJ9: 57.5484 | DK9: 67.1958 | DL9: 61.344835 | DM9: 67.689491 | DN9: 73.25304 | DO9: 74.64198 | DP9: 79.632 | DQ9: 73.779632 | DR9: 74.8776 | DS9: 82.238 | DT9: 87.423382 | DU9: 84.6566 | DV9: 84.647033 | DW9: 86.747713 | DX9: 90.847768 | DY9: 94.182261 | DZ9: 81.28449 | EA9: 69.015567 | EB9: 72.0832 | EC9: 77.708842 | ED9: 79.0566 | EE9: 81.5034 | EF9: 80.225536 | EG9: 73.06866 | EH9: 76.6082 | EI9: 72.879545 | EJ9: 77.56056 | EK9: 76.282774 | EL9: 74.243621 | EM9: 77.0518 | EN9: 72.8078 | EO9: 62.952916 | EP9: 43.115864 | EQ9: 27.4876 | ER9: 31.17072 | ES9: 41.835818 | ET9: 45.753273 | EU9: 46.4864 | EV9: 42.303 | EW9: 44.441727 | EX9: 48.130011 | EY9: 56.407527 | EZ9: 59.687084 | FA9: 67.236695 | FB9: 70.246643 | FC9: 68.4642 | FD9: 72.77382 | FE9: 76.967482 | FF9: 77.3088 | FG9: 75.104782 | FH9: 83.5382 | FI9: 96.42 | FJ9: 90.66645 | FL9: 68.158586 | FM9: 88.43922 | FN9: 122.76752 | FO9: 126.02047 | FP9: 121.75227 | FQ9: 111.38596 | FR9: 63.807554 | FS9: 51.024839 | FT9: 63.416249 | FU9: 82.444337 | FV9: 76.522728 | FW9: 46.907721 | FX9: =C9 -> 76.219469
A10: 12 | B10: Fuel Oil # 2 (US$/MMBTU) | C10: 13.853048 | D10: 8.3686119 | E10: 5.4844359 | F10: 0.6553579 | H10: 13.899424 | I10: -5.5308121 | J10: -0.39791664 | L10: 10.705453 | M10: 9.4079971 | N10: 9.409542 | O10: 10.171592 | P10: 11.161305 | Q10: 13.342348 | R10: 12.39522 | S10: 14.193566 | T10: 13.18884 | U10: 14.686867 | V10: 15.07639 | W10: 14.916464 | X10: 15.460587 | Y10: 14.917718 | Z10: 15.755543 | AA10: 16.784642 | AB10: 15.421469 | AC10: 15.366863 | AD10: 14.995547 | AE10: 15.444604 | AF10: 15.821374 | AG10: 16.968611 | AH10: 17.471183 | AI10: 18.480014 | AJ10: 19.571069 | AK10: 20.897147 | AL10: 22.955061 | AM10: 24.281152 | AN10: 22.463577 | AO10: 22.545038 | AP10: 23.283779 | AQ10: 22.289413 | AR10: 22.166103 | AS10: 22.375645 | AT10: 23.159351 | AU10: 21.771701 | AV10: 23.031527 | AW10: 24.134351 | AX10: 24.463914 | AY10: 24.045763 | AZ10: 22.243164 | BA10: 19.961069 | BB10: 21.249146 | BC10: 23.127282 | BD10: 23.929209 | BE10: 23.667541 | BF10: 22.519618 | BG10: 22.481221 | BH10: 23.07121 | BI10: 24.055966 | BJ10: 22.250229 | BK10: 20.928279 | BL10: 20.835288 | BM10: 21.161679 | BN10: 21.920749 | BO10: 22.60975 | BP10: 22.447443 | BQ10: 22.209293 | BR10: 21.6409 | BS10: 22.413959 | BT10: 21.942821 | BU10: 21.991965 | BV10: 21.773064 | BW10: 22.013668 | BX10: 21.825663 | BY10: 21.972083 | BZ10: 21.373664 | CA10: 21.145147 | CB10: 20.192439 | CC10: 18.509559 | CD10: 16.990076 | CE10: 13.205416 | CF10: 11.770305 | CG10: 13.362133 | CH10: 12.503435 | CI10: 13.101781 | CJ10: 14.082176 | CK10: 13.166794 | CL10: 11.769674 | CM10: 10.538204 | CN10: 10.59502 | CO10: 10.585774 | CP10: 9.8680595 | CQ10: 7.8225191 | CR10: 6.933628 | CS10: 6.9215649 | CT10: 7.6062457 | CU10: 8.4711014 | CV10: 9.7716467 | CW10: 10.47696 | CX10: 9.3562977 | CY10: 9.7055592 | CZ10: 9.9348601 | DA10: 10.92879 | DB10: 9.9727481 | DC10: 11.207052 | DD10: 11.490731 | DE10: 11.613777 | DF10: 10.789678 | DG10: 11.110566 | DH10: 10.540874 | DI10: 9.7617974 | DJ10: 10.459542 | DK10: 12.212977 | DL10: 11.149552 | DM10: 12.302706 | DN10: 13.313893 | DO10: 13.566336 | DP10: 14.473282 | DQ10: 13.409602 | DR10: 13.60916 | DS10: 14.946928 | DT10: 15.889382 | DU10: 15.386514 | DV10: 15.384775 | DW10: 15.766578 | DX10: 16.511772 | DY10: 17.117823 | DZ10: 14.773626 | EA10: 12.543723 | EB10: 13.101272 | EC10: 14.123744 | ED10: 14.368702 | EE10: 14.813413 | EF10: 14.581159 | EG10: 13.280382 | EH10: 13.9237 | EI10: 13.24601 | EJ10: 14.096794 | EK10: 13.864554 | EL10: 13.493933 | EM10: 14.004326 | EN10: 13.23297 | EO10: 11.441824 | EP10: 7.8363983 | EQ10: 4.9959288 | ER10: 5.6653435 | ES10: 7.6037474 | ET10: 8.3157529 | EU10: 8.4490004 | EV10: 7.6886587 | EW10: 8.0773768 | EX10: 8.74773 | EY10: 10.252186 | EZ10: 10.848252 | FA10: 12.22041 | FB10: 12.767474 | FC10: 12.443511 | FD10: 13.226794 | FE10: 13.989001 | FF10: 14.051036 | FG10: 13.650451 | FH10: 15.183242 | FI10: 17.524537 | FJ10: 16.478817 | FL10: 12.387965 | FM10: 16.074013 | FN10: 22.313253 | FO10: 22.904484 | FP10: 22.128729 | FQ10: 20.24463 | FR10: 11.597156 | FS10: 9.2738711 | FT10: 11.526036 | FU10: 14.984431 | FV10: 13.908166 | FW10: 8.5255764 | FX10: =C10 -> 13.853048
A11: 9 | B11: Fuel Oil # 6 (US$/BBL) | C11: 60.029948 | D11: 34.403853 | E11: 25.626095 | F11: 0.74486118 | H11: 54.717104 | I11: -20.31325 | J11: -0.37124133 | L11: 38.6775 | M11: 40.6289 | N11: 37.608 | O11: 42.8619 | P11: 52.2375 | Q11: 60.1477 | R11: 59.8432 | S11: 66.2107 | T11: 64.0917 | U11: 67.0841 | V11: 71.3105 | W11: 69.067 | X11: 71.4961 | Y11: 69.8368 | Z11: 69.7804 | AA11: 72.9071 | AB11: 66.705 | AC11: 66.0398 | AD11: 66.2548 | AE11: 66.6318 | AF11: 67.169 | AG11: 71.5119 | AH11: 72.4025 | AI11: 75.7114 | AJ11: 79.045 | AK11: 87.9276 | AL11: 95.5141 | AM11: 101.4613 | AN11: 95.4012 | AO11: 98.65 | AP11: 100.5588 | AQ11: 97.4228 | AR11: 97.630952 | AS11: 99.265476 | AT11: 100.31625 | AU11: 95.252381 | AV11: 102.89375 | AW11: 109.09125 | AX11: 111.62159 | AY11: 108.6 | AZ11: 98.593182 | BA11: 86.915476 | BB11: 91.579762 | BC11: 99.518478 | BD11: 100.90263 | BE11: 96.180435 | BF11: 92.93375 | BG11: 93.654 | BH11: 96.698333 | BI11: 98.950526 | BJ11: 95.7855 | BK11: 91.488636 | BL11: 91.141818 | BM11: 89.976 | BN11: 91.294545 | BO11: 93.104545 | BP11: 94.584 | BQ11: 92.10913 | BR11: 89.546316 | BS11: 91.892857 | BT11: 88.237619 | BU11: 90.344737 | BV11: 89.31381 | BW11: 90.735238 | BX11: 91.779524 | BY11: 93.101905 | BZ11: 88.975 | CA11: 87.641429 | CB11: 85.90619 | CC11: 73.147391 | CD11: 63.972222 | CE11: 48.875238 | CF11: 38.487 | CG11: 48.698421 | CH11: 45.855 | CI11: 48.552381 | CJ11: 52.36 | CK11: 51.861818 | CL11: 44.388182 | CM11: 35.175238 | CN11: 34.402381 | CO11: 34.603864 | CP11: 31.723684 | CQ11: 23.035909 | CR11: 19.054211 | CS11: 20.3665 | CT11: 23.640909 | CU11: 25.910476 | CV11: 31.819524 | CW11: 35.049091 | CX11: 33.8275 | CY11: 34.37 | CZ11: 36.410476 | DA11: 40.091905 | DB11: 38.1235 | DC11: 45.313333 | DD11: 46.648 | DE11: 46.948 | DF11: 43.35 | DG11: 44.524737 | DH11: 43.760455 | DI11: 41.572727 | DJ11: 44.596316 | DK11: 47.43 | DL11: 48.788 | DM11: 49.368636 | DN11: 55.234 | DO11: 54.2005 | DP11: 56.795714 | DQ11: 54.146316 | DR11: 54.357143 | DS11: 57.545238 | DT11: 64.940909 | DU11: 64.644762 | DV11: 67.159524 | DW11: 63.893478 | DX11: 66.354737 | DY11: 70.510435 | DZ11: 61.483 | EA11: 52.828333 | EB11: 55.820952 | EC11: 63.532105 | ED11: 63.990952 | EE11: 66.04619 | EF11: 61.661818 | EG11: 55.7805 | EH11: 58.92 | EI11: 45.339091 | EJ11: 50.4655 | EK11: 43.022609 | EL11: 37.308421 | EM11: 41.417143 | EN11: 43.393333 | EO11: 44.618421 | EP11: 24.928636 | EQ11: 17.28619 | ER11: 23.965 | ES11: 32.899545 | ET11: 37.432727 | EU11: 40.315714 | EV11: 36.125714 | EW11: 37.695 | EX11: 39.782105 | EY11: 44.087273 | EZ11: 48.4758 | FA11: 53.446842 | FB11: 55.751957 | FC11: 56.289762 | FD11: 57.82525 | FE11: 61.712727 | FF11: 61.661905 | FG11: 60.64 | FH11: 65.202381 | FI11: 72.97381 | FJ11: 66.349 | FL11: 55.814058 | FM11: 69.703883 | FN11: 95.703822 | FO11: 99.373692 | FP11: 93.047684 | FQ11: 82.669192 | FR11: 40.76199 | FS11: 31.998119 | FT11: 47.201781 | FU11: 61.221632 | FV11: 53.608774 | FW11: 35.210805 | FX11: =C11 -> 60.029948
A12: 13 | B12: Fuel Oil # 6 (US$/MMBTU) | C12: 10.136769 | D12: 5.8094991 | E12: 4.3272704 | F12: 0.74486118 | H12: 9.2396325 | I12: -3.4301334 | J12: -0.37124133 | L12: 6.531155 | M12: 6.8606721 | N12: 6.3505572 | O12: 7.2377406 | P12: 8.820922 | Q12: 10.156653 | R12: 10.105235 | S12: 11.180463 | T12: 10.822644 | U12: 11.327947 | V12: 12.041624 | W12: 11.662783 | X12: 12.072965 | Y12: 11.792773 | Z12: 11.783249 | AA12: 12.311229 | AB12: 11.263931 | AC12: 11.151604 | AD12: 11.187909 | AE12: 11.25157 | AF12: 11.342283 | AG12: 12.075633 | AH12: 12.226022 | AI12: 12.784769 | AJ12: 13.347687 | AK12: 14.847619 | AL12: 16.12869 | AM12: 17.132945 | AN12: 16.109625 | AO12: 16.658224 | AP12: 16.980547 | AQ12: 16.450996 | AR12: 16.486145 | AS12: 16.762154 | AT12: 16.93959 | AU12: 16.084495 | AV12: 17.374831 | AW12: 18.421353 | AX12: 18.848631 | AY12: 18.338399 | AZ12: 16.648629 | BA12: 14.67671 | BB12: 15.46433 | BC12: 16.804876 | BD12: 17.038607 | BE12: 16.241208 | BF12: 15.692967 | BG12: 15.81459 | BH12: 16.328661 | BI12: 16.708971 | BJ12: 16.174519 | BK12: 15.448942 | BL12: 15.390378 | BM12: 15.193516 | BN12: 15.416168 | BO12: 15.721808 | BP12: 15.971631 | BQ12: 15.55372 | BR12: 15.120958 | BS12: 15.5172 | BT12: 14.899969 | BU12: 15.255781 | BV12: 15.081697 | BW12: 15.321722 | BX12: 15.498062 | BY12: 15.721362 | BZ12: 15.024485 | CA12: 14.799296 | CB12: 14.50628 | CC12: 12.351805 | CD12: 10.802469 | CE12: 8.2531641 | CF12: 6.4989868 | CG12: 8.2233065 | CH12: 7.7431611 | CI12: 8.1986459 | CJ12: 8.8416076 | CK12: 8.7574837 | CL12: 7.4954714 | CM12: 5.9397565 | CN12: 5.8092504 | CO12: 5.8432732 | CP12: 5.3569207 | CQ12: 3.8898867 | CR12: 3.2175296 | CS12: 3.4391253 | CT12: 3.9920481 | CU12: 4.3752915 | CV12: 5.3731043 | CW12: 5.9184551 | CX12: 5.7121749 | CY12: 5.8037825 | CZ12: 6.1483411 | DA12: 6.769994 | DB12: 6.4376055 | DC12: 7.6516942 | DD12: 7.8770686 | DE12: 7.9277271 | DF12: 7.3201621 | DG12: 7.5185304 | DH12: 7.3894722 | DI12: 7.0200485 | DJ12: 7.5306173 | DK12: 8.0091185 | DL12: 8.238433 | DM12: 8.3364803 | DN12: 9.3269166 | DO12: 9.1523978 | DP12: 9.5906306 | DQ12: 9.1432482 | DR12: 9.1788488 | DS12: 9.7171966 | DT12: 10.966043 | DU12: 10.916035 | DV12: 11.340683 | DW12: 10.789172 | DX12: 11.204785 | DY12: 11.906524 | DZ12: 10.382134 | EA12: 8.9206912 | EB12: 9.4260305 | EC12: 10.72815 | ED12: 10.805632 | EE12: 11.152683 | EF12: 10.41233 | EG12: 9.4191996 | EH12: 9.9493414 | EI12: 7.6560437 | EJ12: 8.5216988 | EK12: 7.2648782 | EL12: 6.2999698 | EM12: 6.9937762 | EN12: 7.3274795 | EO12: 7.5343501 | EP12: 4.2094962 | EQ12: 2.9189785 | ER12: 4.0467747 | ES12: 5.5554788 | ET12: 6.3209604 | EU12: 6.8077869 | EV12: 6.1002557 | EW12: 6.3652482 | EX12: 6.7176807 | EY12: 7.4446594 | EZ12: 8.1857143 | FA12: 9.0251338 | FB12: 9.4143797 | FC12: 9.5051945 | FD12: 9.7644799 | FE12: 10.420927 | FF12: 10.412345 | FG12: 10.239784 | FH12: 11.010196 | FI12: 12.322494 | FJ12: 11.203816 | FL12: 9.4248663 | FM12: 11.770328 | FN12: 16.160726 | FO12: 16.780428 | FP12: 15.712206 | FQ12: 13.959674 | FR12: 6.8831459 | FS12: 5.4032622 | FT12: 7.970581 | FU12: 10.337999 | FV12: 9.0524778 | FW12: 5.9457624 | FX12: =C12 -> 10.136769
A13: 10 | B13: Gas Natural (US$/MMBTU) | C13: 3.4511999 | D13: 2.0353421 | E13: 1.4158578 | F13: 0.69563626 | H13: 2.6928762 | I13: -0.65753402 | J13: -0.24417537 | L13: 5.7933 | M13: 5.1954 | N13: 4.4096842 | O13: 4.0367 | P13: 3.5966 | Q13: 3.8816 | R13: 3.9373 | S13: 3.5682 | T13: 3.3675 | U13: 3.2839 | V13: 4.7618 | W13: 4.6042 | X13: 5.2869 | Y13: 5.6522 | Z13: 5.2503 | AA13: 4.3756 | AB13: 4.0809 | AC13: 4.1173 | AD13: 4.7597 | AE13: 4.562 | AF13: 4.3143 | AG13: 3.887 | AH13: 3.5951 | AI13: 3.9998 | AJ13: 4.2709 | AK13: 4.4882 | AL13: 4.0724 | AM13: 4.0387 | AN13: 4.2454 | AO13: 4.3402 | AP13: 4.5385 | AQ13: 4.3683 | AR13: 4.0021 | AS13: 3.8752 | AT13: 3.6028 | AU13: 3.5922 | AV13: 3.3019 | AW13: 2.7478 | AX13: 2.53 | AY13: 2.3347 | AZ13: 2.0384 | BA13: 2.4766 | BB13: 2.4646 | BC13: 2.9214 | BD13: 2.8455 | BE13: 2.8614 | BF13: 3.4663 | BG13: 3.6848 | BH13: 3.4636 | BI13: 3.3569 | BJ13: 3.3013 | BK13: 3.7144 | BL13: 4.132 | BM13: 4.1010455 | BN13: 3.8492 | BO13: 3.6535 | BP13: 3.3981 | BQ13: 3.6206 | BR13: 3.652 | BS13: 3.6074 | BT13: 4.2523 | BU13: 4.4908 | BV13: 5.2067 | BW13: 4.4984 | BX13: 4.5708 | BY13: 4.5616 | BZ13: 4.6048 | CA13: 4.0812 | CB13: 3.8764 | CC13: 3.9129 | CD13: 3.8261 | CE13: 4.1954 | CF13: 3.5699 | CG13: 3.0436 | CH13: 2.7512 | CI13: 2.7488 | CJ13: 2.5851 | CK13: 2.8564 | CL13: 2.7613 | CM13: 2.8147 | CN13: 2.7573 | CO13: 2.6529 | CP13: 2.4092 | CQ13: 2.2832 | CR13: 2.0388 | CS13: 2.2371 | CT13: 1.9784 | CU13: 1.7862 | CV13: 2.0000476 | CW13: 2.0738571 | CX13: 2.5633636 | CY13: 2.7633 | CZ13: 2.7238696 | DA13: 2.8957143 | DB13: 3.061619 | DC13: 2.8473333 | DD13: 3.543 | DE13: 3.35 | DF13: 2.9531579 | DG13: 2.9526957 | DH13: 3.2492273 | DI13: 2.9999091 | DJ13: 2.9999091 | DK13: 2.97225 | DL13: 2.8945652 | DM13: 3.00365 | DN13: 2.9199545 | DO13: 3.0425714 | DP13: 2.7986667 | DQ13: 3.1451905 | DR13: 2.7065789 | DS13: 2.6955238 | DT13: 2.7193333 | DU13: 2.8155455 | DV13: 2.9412381 | DW13: 2.8029048 | DX13: 2.898913 | DY13: 2.8815789 | DZ13: 3.1912609 | EA13: 3.9589524 | EB13: 4.1080526 | EC13: 3.1371 | ED13: 2.6855789 | EE13: 2.8159524 | EF13: 2.6129048 | EG13: 2.6 | EH13: 2.3488 | EI13: 2.3232857 | EJ13: 2.1644545 | EK13: 2.5119 | EL13: 2.3136087 | EM13: 2.65855 | EN13: 2.307619 | EO13: 2.0635238 | EP13: 1.8571053 | EQ13: 1.7511304 | ER13: 1.8059444 | ES13: 1.81625 | ET13: 1.7106818 | EU13: 1.7573182 | EV13: 2.2644762 | EW13: 2.2897143 | EX13: 2.765 | EY13: 2.91845 | EZ13: 2.619 | FA13: 2.6346842 | FB13: 2.9001579 | FC13: 2.6358261 | FD13: 2.656 | FE13: 2.9581111 | FF13: 3.2116818 | FG13: 3.7820476 | FH13: 4.0005 | FI13: 4.9880952 | FJ13: 5.5770952 | FL13: 4.2030154 | FM13: 4.4900917 | FN13: 4.119575 | FO13: 2.8061167 | FP13: 3.6541705 | FQ13: 4.3397833 | FR13: 2.7694667 | FS13: 2.4141337 | FT13: 3.0734075 | FU13: 2.9629739 | FV13: 2.6900156 | FW13: 2.1089345 | FX13: =C13 -> 3.4511999
B14: Gas Natural Conversion (US$/MMBTU) | C14: 9.46888 | D14: 8.1094962 | E14: 1.3593837 | F14: 0.16762863 | H14: 0 | I14: 8.1094962 | J14: 0 | L14: 0 | M14: 0 | N14: 0 | O14: 0 | P14: 0 | Q14: 0 | R14: 0 | S14: 0 | T14: 0 | U14: 0 | V14: 0 | W14: 0 | X14: 0 | Y14: 0 | Z14: 0 | AA14: 0 | AB14: 0 | AC14: 0 | AD14: 0 | AE14: 0 | AF14: 0 | AG14: 0 | AH14: 0 | AI14: 0 | AJ14: 0 | AK14: 0 | AL14: 0 | AM14: 0 | AN14: 0 | AO14: 0 | AP14: 0 | AQ14: 0 | AR14: 0 | AS14: 0 | AT14: 0 | AU14: 0 | AV14: 0 | AW14: 0 | AX14: 0 | AY14: 0 | AZ14: 0 | BA14: 0 | BB14: 0 | BC14: 0 | BD14: 0 | BE14: 0 | BF14: 0 | BG14: 0 | BH14: 0 | BI14: 0 | BJ14: 0 | BK14: 0 | BL14: 0 | BM14: 0 | BN14: 0 | BO14: 0 | BP14: 0 | BQ14: 0 | BR14: 0 | BS14: 0 | BT14: 0 | BU14: 0 | BV14: 0 | BW14: 0 | BX14: 0 | BY14: 0 | BZ14: 0 | CA14: 0 | CB14: 0 | CC14: 0 | CD14: 0 | CE14: 0 | CF14: 0 | CG14: 0 | CH14: 0 | CI14: 0 | CJ14: 0 | CK14: 0 | CL14: 0 | CM14: 0 | CN14: 0 | CO14: 0 | CP14: 0 | CQ14: 0 | CR14: 0 | CS14: 0 | CT14: 0 | CU14: 0 | CV14: 0 | CW14: 0 | CX14: 0 | CY14: 0 | CZ14: 0 | DA14: 0 | DB14: 0 | DC14: 0 | DD14: 0 | DE14: 0 | DF14: 0 | DG14: 0 | DH14: 0 | DI14: 0 | DJ14: 0 | DK14: 0 | DL14: 0 | DM14: 0 | DN14: 0 | DO14: 0 | DP14: 0 | DQ14: 0 | DR14: 0 | DS14: 0 | DT14: 0 | DU14: 0 | DV14: 0 | DW14: 0 | DX14: 0 | DY14: 0 | DZ14: 0 | EA14: 0 | EB14: 0 | EC14: 0 | ED14: 0 | EE14: 0 | EF14: 0 | EG14: 0 | EH14: 0 | EI14: 0 | EJ14: 0 | EK14: 0 | EL14: 0 | EM14: 0 | EN14: 0 | EO14: 0 | EP14: 0 | EQ14: 0 | ER14: 0 | ES14: 0 | ET14: 0 | EU14: 7.5209159 | EV14: 8.1041476 | EW14: 8.1331714 | EX14: 8.67975 | EY14: 8.8562175 | EZ14: 8.51185 | FA14: 8.5298868 | FB14: 8.8351816 | FC14: 8.5312 | FD14: 8.5544 | FE14: 8.9018278 | FF14: 9.1934341 | FG14: 9.8493548 | FH14: 10.100575 | FI14: 11.23631 | FJ14: 11.91366 | FL14: 0 | FM14: 0 | FN14: 0 | FO14: 0 | FP14: 0 | FQ14: 0 | FR14: 0 | FS14: 0 | FT14: 0 | FU14: 0 | FV14: 0 | FW14: 8.2588405 | FX14: =C14 -> 9.46888
A15: 11 | B15: Carbón Mineral (US$/Ton) | C15: 113.89773 | D15: 50.660303 | E15: 63.237424 | F15: 1.2482638 | H15: 57.625978 | I15: -6.9656749 | J15: -0.12087734 | L15: 77.1 | M15: 69.38 | N15: 56.63 | O15: 58.5 | P15: 54.9 | Q15: 56.31 | R15: 57.1 | S15: 57 | T15: 52.38 | U15: 55.25 | V15: 54.63 | W15: 57.15 | X15: 62.25 | Y15: 59.63 | Z15: 60.19 | AA15: 68.8 | AB15: 78.13 | AC15: 79.63 | AD15: 81.15 | AE15: 78.75 | AF15: 78.69 | AG15: 84.45 | AH15: 91.13 | AI15: 108.5 | AJ15: 114.88 | AK15: 111.13 | AL15: 116 | AM15: 119.3 | AN15: 114.5 | AO15: 113.8 | AP15: 114.33 | AQ15: 115 | AR15: 111.6625 | AS15: 103 | AT15: 101.125 | AU15: 97.8125 | AV15: 95.8 | AW15: 90.4167 | AX15: 88.3 | AY15: 88 | AZ15: 79.45 | BA15: 78.47 | BB15: 80.875 | BC15: 85.57 | BD15: 80.8125 | BE15: 77.0625 | BF15: 78.45 | BG15: 80.8 | BH15: 78.125 | BI15: 80.3 | BJ15: 78.28 | BK15: 74.65 | BL15: 73.03 | BM15: 66.4625 | BN15: 65.6875 | BO15: 66.53 | BP15: 65.5375 | BQ15: 69.2 | BR15: 72.95 | BS15: 70.5 | BT15: 72.69 | BU15: 69.3375 | BV15: 64.8625 | BW15: 68.0375 | BX15: 67.91 | BY15: 63.675 | BZ15: 66 | CA15: 68.65 | CB15: 66.5125 | CC15: 64.35 | CD15: 68.475 | CE15: 64.933333 | CF15: 55.38 | CG15: 60.045 | CH15: 57.7 | CI15: 55.5 | CJ15: 54.34 | CK15: 53.25 | CL15: 51.875 | CM15: 49.65 | CN15: 49.125 | CO15: 48.56 | CP15: 51.016667 | CQ15: 45 | CR15: 43.0125 | CS15: 41.375 | CT15: 43.8375 | CU15: 44 | CV15: 44.3875 | CW15: 46.775 | CX15: 54.23 | CY15: 57.85 | CZ15: 60.95 | DA15: 78.875 | DB15: 86.6875 | DC15: 89.8 | DD15: 83.75 | DE15: 79.5 | DF15: 68.5 | DG15: 67.95 | DH15: 67.95 | DI15: 73.98 | DJ15: 78.75 | DK15: 79.1875 | DL15: 82.74 | DM15: 84.0625 | DN15: 83.775 | DO15: 83.9 | DP15: 86.375 | DQ15: 81.5 | DR15: 75.8 | DS15: 77.9 | DT15: 83.4375 | DU15: 89.7 | DV15: 93.4375 | DW15: 90.1 | DX15: 91.25 | DY15: 93.3125 | DZ15: 84.3 | EA15: 81.75 | EB15: 79.375 | EC15: 73.25 | ED15: 67.68 | EE15: 55.916667 | EF15: 54.1 | EG15: 47.4 | EH15: 49.875 | EI15: 45.339091 | EJ15: 51.625 | EK15: 54.625 | EL15: 54.7 | EM15: 52.9375 | EN15: 50.38 | EO15: 49.875 | EP15: 48.8125 | EQ15: 47.333333 | ER15: 44.45 | ES15: 48.4375 | ET15: 52 | EU15: 52 | EV15: 53.5 | EW15: 55.1 | EX15: 55.375 | EY15: 61.1 | EZ15: 66.75 | FA15: 68.875 | FB15: 69.625 | FC15: 67.5 | FD15: 75.375 | FE15: 97.25 | FF15: 122.1 | FG15: 138.5 | FH15: 159.5 | FI15: 215.4 | FJ15: 172 | FL15: 58.860833 | FM15: 77.608333 | FN15: 111.045 | FO15: 83.667225 | FP15: 71.771042 | FQ15: 67.119444 | FR15: 52.620139 | FS15: 57.648333 | FT15: 77.837083 | FU15: 85.738542 | FV15: 57.235271 | FW15: 51.530278 | FX15: =C15 -> 113.89773
A16: 14 | B16: Carbón Mineral (US$/MMBTU) | C16: 4.5815659 | D16: 2.0378239 | E16: 2.5437419 | F16: 1.2482638 | H16: 2.31802 | I16: -0.2801961 | J16: -0.12087734 | L16: 3.1013677 | M16: 2.7908286 | N16: 2.2779566 | O16: 2.3531778 | P16: 2.2083669 | Q16: 2.2650845 | R16: 2.2968624 | S16: 2.2928399 | T16: 2.1069992 | U16: 2.2224457 | V16: 2.197506 | W16: 2.2988737 | X16: 2.5040225 | Y16: 2.3986323 | Z16: 2.4211585 | AA16: 2.767498 | AB16: 3.1427997 | AC16: 3.2031376 | AD16: 3.26428 | AE16: 3.1677393 | AF16: 3.1653258 | AG16: 3.3970233 | AH16: 3.6657281 | AI16: 4.3644409 | AJ16: 4.621078 | AK16: 4.4702333 | AL16: 4.6661303 | AM16: 4.7988737 | AN16: 4.6057924 | AO16: 4.5776348 | AP16: 4.5989541 | AQ16: 4.6259051 | AR16: 4.4916533 | AS16: 4.1432019 | AT16: 4.0677796 | AU16: 3.9345334 | AV16: 3.85358 | AW16: 3.6370354 | AX16: 3.5518906 | AY16: 3.539823 | AZ16: 3.195897 | BA16: 3.1564763 | BB16: 3.253218 | BC16: 3.4420756 | BD16: 3.2507039 | BE16: 3.0998592 | BF16: 3.1556718 | BG16: 3.2502011 | BH16: 3.1425986 | BI16: 3.2300885 | BJ16: 3.1488335 | BK16: 3.0028158 | BL16: 2.9376508 | BM16: 2.6734714 | BN16: 2.6422969 | BO16: 2.6761866 | BP16: 2.6362631 | BQ16: 2.7835881 | BR16: 2.9344328 | BS16: 2.8358809 | BT16: 2.9239743 | BU16: 2.7891191 | BV16: 2.609111 | BW16: 2.7368262 | BX16: 2.7316975 | BY16: 2.5613435 | BZ16: 2.6548673 | CA16: 2.7614642 | CB16: 2.6754827 | CC16: 2.5884956 | CD16: 2.7544248 | CE16: 2.6119603 | CF16: 2.227675 | CG16: 2.4153258 | CH16: 2.3209976 | CI16: 2.232502 | CJ16: 2.1858407 | CK16: 2.1419952 | CL16: 2.0866854 | CM16: 1.9971842 | CN16: 1.976066 | CO16: 1.9533387 | CP16: 2.0521588 | CQ16: 1.8101368 | CR16: 1.7301891 | CS16: 1.6643202 | CT16: 1.7633749 | CU16: 1.7699115 | CV16: 1.7854988 | CW16: 1.8815366 | CX16: 2.1814159 | CY16: 2.3270314 | CZ16: 2.4517297 | DA16: 3.1727675 | DB16: 3.4870274 | DC16: 3.6122285 | DD16: 3.3688656 | DE16: 3.1979083 | DF16: 2.7554304 | DG16: 2.7333065 | DH16: 2.7333065 | DI16: 2.9758648 | DJ16: 3.1677393 | DK16: 3.1853379 | DL16: 3.3282381 | DM16: 3.381436 | DN16: 3.3698713 | DO16: 3.3748994 | DP16: 3.474457 | DQ16: 3.2783588 | DR16: 3.0490748 | DS16: 3.1335479 | DT16: 3.3562953 | DU16: 3.608206 | DV16: 3.7585479 | DW16: 3.6242961 | DX16: 3.6705551 | DY16: 3.7535197 | DZ16: 3.3909895 | EA16: 3.2884151 | EB16: 3.1928801 | EC16: 2.9465004 | ED16: 2.7224457 | EE16: 2.2492625 | EF16: 2.1761866 | EG16: 1.9066774 | EH16: 2.0062349 | EI16: 1.8237768 | EJ16: 2.0766291 | EK16: 2.1973049 | EL16: 2.2003218 | EM16: 2.1294248 | EN16: 2.0265487 | EO16: 2.0062349 | EP16: 1.9634956 | EQ16: 1.9039957 | ER16: 1.7880129 | ES16: 1.9484111 | ET16: 2.0917136 | EU16: 2.0917136 | EV16: 2.1520515 | EW16: 2.2164119 | EX16: 2.2274739 | EY16: 2.4577635 | EZ16: 2.6850362 | FA16: 2.7705149 | FB16: 2.8006838 | FC16: 2.7152051 | FD16: 3.0319791 | FE16: 3.9119067 | FF16: 4.9115044 | FG16: 5.5711987 | FH16: 6.4159292 | FI16: 8.6645213 | FJ16: 6.918745 | FL16: 2.3676924 | FM16: 3.1218155 | FN16: 4.4668142 | FO16: 3.365536 | FP16: 2.8870089 | FQ16: 2.6998972 | FR16: 2.1166588 | FS16: 2.3189193 | FT16: 3.131017 | FU16: 3.4488553 | FV16: 2.3023038 | FW16: 2.0728189 | FX16: =C16 -> 4.5815659
B18: Generación de Energía por tipo de combustible
B19: Total Generación | C19: 17813.07 | D19: 16211.883 | E19: 1601.1876 | F19: 0.098766294 | H19: 15946.877 | I19: 265.00545 | J19: 0.016618015 | L19: 922.04842 | M19: 818.5513 | N19: 898.69257 | O19: 917.18353 | P19: 943.30873 | Q19: 982.41699 | R19: 1045.7514 | S19: 1040.5285 | T19: 1014.8929 | U19: 1064.5995 | V19: 973.9716 | W19: 1023.1697 | X19: 948.15589 | Y19: 891.79764 | Z19: 1021.3541 | AA19: 1013.6284 | AB19: 1084.5643 | AC19: 1042.3687 | AD19: 1084.7864 | AE19: 1117.3577 | AF19: 1049.5927 | AG19: 1081.8468 | AH19: 966.62602 | AI19: 969.55713 | AJ19: 963.30584 | AK19: 890.38935 | AL19: 998.47666 | AM19: 1002.0157 | AN19: 1060.2304 | AO19: 1070.0921 | AP19: 1094.807 | AQ19: 1115.2692 | AR19: 1093.6813 | AS19: 1127.1931 | AT19: 1046.0148 | AU19: 1016.834 | AV19: 980.675 | AW19: 948 | AX19: 1019.83 | AY19: 1030.543 | AZ19: 1181.68 | BA19: 1175.746 | BB19: 1211.903 | BC19: 1181.76 | BD19: 1175.886 | BE19: 1202.848 | BF19: 1146.739 | BG19: 1100.28 | BH19: 918.96586 | BI19: 814.9526 | BJ19: 911.30384 | BK19: 953.37083 | BL19: 1073.7916 | BM19: 981.71516 | BN19: 1150.5949 | BO19: 1188.1823 | BP19: 1133.8477 | BQ19: 1084.3878 | BR19: 995.92368 | BS19: 900.38185 | BT19: 1038.6562 | BU19: 950.3367 | BV19: 1099.9252 | BW19: 1090.918 | BX19: 1135.3995 | BY19: 1150.3523 | BZ19: 1216.798 | CA19: 1200.9025 | CB19: 1142.8577 | CC19: 1218.5596 | CD19: 1115.9196 | CE19: 1103.2836 | CF19: 1088.2508 | CG19: 996.01054 | CH19: 1133.9448 | CI19: 1136.6634 | CJ19: 1201.1855 | CK19: 1214.9412 | CL19: 1276.3813 | CM19: 1276.2716 | CN19: 1242.271 | CO19: 1286.8876 | CP19: 1148.8956 | CQ19: 1175.6812 | CR19: 1124.733 | CS19: 1089.2607 | CT19: 1196 | CU19: 1218.353 | CV19: 1313.6868 | CW19: 1271.6447 | CX19: 1344.0761 | CY19: 1337.6032 | CZ19: 1301.8436 | DA19: 1286.9115 | DB19: 1192.4198 | DC19: 1222.9171 | DD19: 1166.8597 | DE19: 1084.8635 | DF19: 1218.2465 | DG19: 1200.4853 | DH19: 1318.045 | DI19: 1306.7353 | DJ19: 1359.1451 | DK19: 1403.6907 | DL19: 1312.6597 | DM19: 1396.0976 | DN19: 1258.5423 | DO19: 1257.0779 | DP19: 1204.6836 | DQ19: 1069.0964 | DR19: 1246.691 | DS19: 1283.513 | DT19: 1335.0744 | DU19: 1360.984 | DV19: 1428.548 | DW19: 1419.2095 | DX19: 1331.2559 | DY19: 1360.2069 | DZ19: 1331.1317 | EA19: 1331.2889 | EB19: 1302.4387 | EC19: 1220.268 | ED19: 1372.7351 | EE19: 1373.6511 | EF19: 1492.2832 | EG19: 1482.4467 | EH19: 1577.4577 | EI19: 1584.2529 | EJ19: 1521.606 | EK19: 1564.2869 | EL19: 1455.451 | EM19: 1464.6197 | EN19: 1405.4504 | EO19: 1347.4261 | EP19: 1316.6857 | EQ19: 1293.3879 | ER19: 1446.7289 | ES19: 1558.1795 | ET19: 1619.0817 | EU19: 1602.3002 | EV19: 1571.5381 | EW19: 1607.3049 | EX19: 1443.7993 | EY19: 1451.372 | EZ19: 1398.4578 | FA19: 1365.4169 | FB19: 1542.4843 | FC19: 1539.2145 | FD19: 1667.1297 | FE19: 1627.7822 | FF19: 1736.1979 | FG19: 1728.9816 | FH19: 1764.7737 | FI19: 1764.2522 | FJ19: 1678.3796 | FL19: 11645.115 | FM19: 12271.636 | FN19: 12478.309 | FO19: 13355.89 | FP19: 12107.418 | FQ19: 13463.909 | FR19: 14177.385 | FS19: 14899.449 | FT19: 15282.449 | FU19: 15701.683 | FV19: 17411.497 | FW19: 17663.255 | FX19: =C19 -> 17813.07
B20: Carbón Mineral | C20: 5573.407 | D20: 6011.0596 | E20: -437.65264 | F20: -0.072807903 | H20: 3147.7599 | I20: 2863.2997 | J20: 0.90963091 | L20: 180.73189 | M20: 114.72025 | N20: 126.3082 | O20: 139.8629 | P20: 161.86797 | Q20: 136.65605 | R20: 168.8417 | S20: 159.2608 | T20: 172.1727 | U20: 188.2451 | V20: 184.9449 | W20: 193.7253 | X20: 181.0222 | Y20: 136.3036 | Z20: 195.1545 | AA20: 173.8431 | AB20: 178.3092 | AC20: 155.9941 | AD20: 96.33377 | AE20: 95.54638 | AF20: 129.1356 | AG20: 163.3322 | AH20: 169.0025 | AI20: 180.5036 | AJ20: 173.69175 | AK20: 141.27538 | AL20: 179.45588 | AM20: 166.36899 | AN20: 175.63835 | AO20: 158.47094 | AP20: 99.084291 | AQ20: 118.15267 | AR20: 169.1168 | AS20: 104.10654 | AT20: 179.25153 | AU20: 177.90639 | AV20: 193.341 | AW20: 167.277 | AX20: 166.029 | AY20: 155.405 | AZ20: 185.259 | BA20: 133.246 | BB20: 164.371 | BC20: 168.319 | BD20: 185.1 | BE20: 172.049 | BF20: 135.791 | BG20: 101.642 | BH20: 26.927598 | BI20: 25.473518 | BJ20: 28.649248 | BK20: 27.715653 | BL20: 29.287192 | BM20: 27.076533 | BN20: 189.90356 | BO20: 194.64735 | BP20: 160.94923 | BQ20: 176.45955 | BR20: 192.1552 | BS20: 111.24065 | BT20: 197.82194 | BU20: 124.96989 | BV20: 191.04104 | BW20: 153.52174 | BX20: 199.35918 | BY20: 193.93111 | BZ20: 195.70767 | CA20: 192.01894 | CB20: 180.54749 | CC20: 183.45777 | CD20: 185.42385 | CE20: 203.26735 | CF20: 198.80768 | CG20: 143.30717 | CH20: 153.22181 | CI20: 146.96281 | CJ20: 166.35303 | CK20: 169.03868 | CL20: 189.53084 | CM20: 184.48432 | CN20: 189.38363 | CO20: 191.65864 | CP20: 175.16277 | CQ20: 191.72707 | CR20: 200.53224 | CS20: 168.42402 | CT20: 127.2897 | CU20: 138.85773 | CV20: 175.44089 | CW20: 195.96862 | CX20: 192.52377 | CY20: 192.01358 | CZ20: 177.47579 | DA20: 199.23246 | DB20: 183.85229 | DC20: 189.02996 | DD20: 197.3957 | DE20: 117.34558 | DF20: 151.07638 | DG20: 165.51834 | DH20: 146.07355 | DI20: 183.23751 | DJ20: 192.99292 | DK20: 198.8427 | DL20: 193.03355 | DM20: 195.47929 | DN20: 170.59646 | DO20: 206.01394 | DP20: 195.89696 | DQ20: 173.03221 | DR20: 188.74981 | DS20: 181.02473 | DT20: 105.98117 | DU20: 124.45685 | DV20: 135.18714 | DW20: 180.33436 | DX20: 161.42698 | DY20: 194.61203 | DZ20: 190.54242 | EA20: 203.18825 | EB20: 199.46885 | EC20: 183.53188 | ED20: 176.76904 | EE20: 280.20021 | EF20: 295.39771 | EG20: 191.81828 | EH20: 339.78835 | EI20: 308.73641 | EJ20: 358.20952 | EK20: 420.86132 | EL20: 392.97833 | EM20: 476.09807 | EN20: 464.14452 | EO20: 485.29229 | EP20: 427.41664 | EQ20: 419.40655 | ER20: 640.9533 | ES20: 598.52948 | ET20: 654.73319 | EU20: 582.23064 | EV20: 629.06089 | EW20: 589.29095 | EX20: 520.00114 | EY20: 539.56558 | EZ20: 341.39298 | FA20: 295.90849 | FB20: 421.23452 | FC20: 509.15782 | FD20: 552.69216 | FE20: 556.25901 | FF20: 627.01397 | FG20: 588.47984 | FH20: 533.35606 | FI20: 619.75474 | FJ20: 528.15738 | FL20: 1927.3378 | FM20: 1854.4808 | FN20: 1842.5195 | FO20: 1927.829 | FP20: 1190.4853 | FQ20: 2201.068 | FR20: 2099.6384 | FS20: 2140.6411 | FT20: 2117.6059 | FU20: 2034.4329 | FV20: 3623.858 | FW20: 6550.6252 | FX20: =C20 -> 5573.407
B21: Gas Natural | C21: 7179.0384 | D21: 4676.7396 | E21: 2502.2988 | F21: 0.53505198 | H21: 4703.9527 | I21: -27.213084 | J21: -0.0057851525 | L21: 144.6669 | M21: 160.5582 | N21: 199.4615 | O21: 158.81113 | P21: 83.6026 | Q21: 206.98518 | R21: 212.6697 | S21: 232.42 | T21: 187.147 | U21: 217.4535 | V21: 199.6551 | W21: 225.656 | X21: 229.8596 | Y21: 237.0705 | Z21: 257.5413 | AA21: 283.7555 | AB21: 290.6041 | AC21: 246.2251 | AD21: 307.152 | AE21: 323.4835 | AF21: 288.944 | AG21: 319.2311 | AH21: 276.1185 | AI21: 283.3471 | AJ21: 345.39022 | AK21: 319.41372 | AL21: 260.5236 | AM21: 319.94904 | AN21: 312.11014 | AO21: 311.88686 | AP21: 353.80397 | AQ21: 333.91837 | AR21: 335.94337 | AS21: 353.65726 | AT21: 328.49034 | AU21: 329.00359 | AV21: 243.644 | AW21: 292.044 | AX21: 366.721 | AY21: 378.011 | AZ21: 420.798 | BA21: 409.969 | BB21: 396.513 | BC21: 423.473 | BD21: 421.208 | BE21: 418.412 | BF21: 417.075 | BG21: 440.053 | BH21: 276.96145 | BI21: 259.79393 | BJ21: 308.04544 | BK21: 354.23314 | BL21: 366.53013 | BM21: 335.99136 | BN21: 354.04918 | BO21: 324.95544 | BP21: 351.48273 | BQ21: 337.13847 | BR21: 279.86575 | BS21: 319.15781 | BT21: 369.22379 | BU21: 344.75892 | BV21: 414.86759 | BW21: 399.54863 | BX21: 393.38648 | BY21: 392.41552 | BZ21: 411.94705 | CA21: 409.3575 | CB21: 369.27979 | CC21: 391.30146 | CD21: 335.16256 | CE21: 365.98092 | CF21: 275.68358 | CG21: 191.06041 | CH21: 395.75322 | CI21: 396.31356 | CJ21: 386.51887 | CK21: 375.42223 | CL21: 391.19833 | CM21: 397.50918 | CN21: 374.68346 | CO21: 382.63516 | CP21: 387.63287 | CQ21: 422.68669 | CR21: 402.81022 | CS21: 328.08913 | CT21: 391.57077 | CU21: 414.42021 | CV21: 368.65667 | CW21: 337.20255 | CX21: 350.77204 | CY21: 373.64135 | CZ21: 363.51108 | DA21: 414.61844 | DB21: 388.98946 | DC21: 417.42149 | DD21: 267.03798 | DE21: 322.03828 | DF21: 370.33686 | DG21: 411.43175 | DH21: 460.58904 | DI21: 477.07466 | DJ21: 451.07465 | DK21: 528.04727 | DL21: 494.8645 | DM21: 526.5389 | DN21: 510.22875 | DO21: 520.92794 | DP21: 443.51702 | DQ21: 411.34766 | DR21: 410.90119 | DS21: 506.18152 | DT21: 520.55157 | DU21: 505.64908 | DV21: 518.69983 | DW21: 521.36768 | DX21: 324.86167 | DY21: 396.43984 | DZ21: 380.51423 | EA21: 403.76447 | EB21: 440.12589 | EC21: 351.64779 | ED21: 397.52649 | EE21: 338.11532 | EF21: 436.53967 | EG21: 452.2979 | EH21: 467.00366 | EI21: 494.84065 | EJ21: 388.21938 | EK21: 448.76015 | EL21: 488.87578 | EM21: 508.75982 | EN21: 478.13762 | EO21: 323.75213 | EP21: 350.10375 | EQ21: 351.53817 | ER21: 340.38609 | ES21: 360.88514 | ET21: 311.12601 | EU21: 532.41214 | EV21: 439.42093 | EW21: 606.02555 | EX21: 582.95206 | EY21: 622.29549 | EZ21: 628.06763 | FA21: 653.75473 | FB21: 695.1036 | FC21: 621.25565 | FD21: 684.06261 | FE21: 587.38463 | FF21: 622.71536 | FG21: 580.0734 | FH21: 705.69527 | FI21: 690.57803 | FJ21: 710.34747 | FL21: 2229.0868 | FM21: 3343.3323 | FN21: 3904.0905 | FO21: 4627.921 | FP21: 3868.2048 | FQ21: 4597.2302 | FR21: 4377.0976 | FS21: 4551.7034 | FT21: 5340.1906 | FU21: 5343.7958 | FV21: 5212.7125 | FW21: 5299.0351 | FX21: =C21 -> 7179.0384
B22: Fuel Oil No. 2 | C22: 36.727325 | D22: 144.96403 | E22: -108.2367 | F22: -0.74664525 | H22: 1105.1427 | I22: -960.17869 | J22: -0.86882777 | L22: 32.56563 | M22: 31.4068 | N22: 45.00641 | O22: 77.58731 | P22: 105.38252 | Q22: 73.999 | R22: 90.36366 | S22: 102.56099 | T22: 76.0039 | U22: 59.0232 | V22: 61.4323 | W22: 44.4491 | X22: 0.8075 | Y22: 0.6574 | Z22: 54.0537 | AA22: 46.8456 | AB22: 40.2445 | AC22: 29.4926 | AD22: 25.3445 | AE22: 28.2142 | AF22: 11.6574 | AG22: 3.7237 | AH22: 8.2578 | AI22: 10.9999 | AJ22: 17.834612 | AK22: 6.8083313 | AL22: 70.757402 | AM22: 54.928247 | AN22: 95.014113 | AO22: 70.089367 | AP22: 99.770045 | AQ22: 126.4215 | AR22: 82.648066 | AS22: 101.70014 | AT22: 58.972407 | AU22: 54.517903 | AV22: 95.994 | AW22: 61.835 | AX22: 46.946 | AY22: 49.154 | AZ22: 38.88 | BA22: 98.727 | BB22: 72.706 | BC22: 53.404 | BD22: 33.06 | BE22: 46.789 | BF22: 96.001 | BG22: 86.569 | BH22: 69.098393 | BI22: 51.786869 | BJ22: 39.980739 | BK22: 61.037643 | BL22: 98.821346 | BM22: 25.319085 | BN22: 14.71397 | BO22: 64.820541 | BP22: 48.369278 | BQ22: 10.709336 | BR22: 2.6964508 | BS22: 0.94560826 | BT22: 1.450941 | BU22: 12.362486 | BV22: 0.26298027 | BW22: 2.5164767 | BX22: 0.52124392 | BY22: 6.3247172 | BZ22: 23.850555 | CA22: 8.2042075 | CB22: 19.463012 | CC22: 16.855069 | CD22: 64.379245 | CE22: 10.681114 | CF22: 66.613439 | CG22: 125.60676 | CH22: 25.610016 | CI22: 42.263635 | CJ22: 97.338052 | CK22: 119.72252 | CL22: 118.36721 | CM22: 130.29496 | CN22: 133.30949 | CO22: 155.86831 | CP22: 76.252134 | CQ22: 47.607449 | CR22: 31.930188 | CS22: 92.568718 | CT22: 128.33317 | CU22: 120.62496 | CV22: 122.44918 | CW22: 114.00655 | CX22: 148.24334 | CY22: 146.84397 | CZ22: 129.79001 | DA22: 98.412729 | DB22: 32.017979 | DC22: 20.096722 | DD22: 25.920413 | DE22: 53.494506 | DF22: 55.58266 | DG22: 35.74106 | DH22: 17.184703 | DI22: 34.504817 | DJ22: 71.864085 | DK22: 53.418593 | DL22: 50.359962 | DM22: 60.530697 | DN22: 59.198726 | DO22: 1.7496273 | DP22: 22.719474 | DQ22: 0 | DR22: 46.305846 | DS22: 14.850049 | DT22: 54.277172 | DU22: 80.290643 | DV22: 106.26964 | DW22: 94.593983 | DX22: 154.09552 | DY22: 92.141328 | DZ22: 112.88657 | EA22: 86.307907 | EB22: 40.358736 | EC22: 87.636615 | ED22: 157.64367 | EE22: 119.26297 | EF22: 106.46999 | EG22: 106.30003 | EH22: 95.522076 | EI22: 84.834864 | EJ22: 153.93338 | EK22: 101.56017 | EL22: 51.620208 | EM22: 16.401874 | EN22: 8.4128991 | EO22: 20.018546 | EP22: 14.198453 | EQ22: 0.80405177 | ER22: 2.3181938 | ES22: 24.750912 | ET22: 56.770186 | EU22: 2.6962518 | EV22: 12.94265 | EW22: 1.3812055 | EX22: 0.67068113 | EY22: 0 | EZ22: 1.6206006 | FA22: 2.2481987 | FB22: 1.3343845 | FC22: 0 | FD22: 1.9054344 | FE22: 4.2073443 | FF22: 0.41693007 | FG22: 6.4790696 | FH22: 11.834727 | FI22: 0 | FJ22: 6.680636 | FL22: 799.78082 | FM22: 260.2988 | FN22: 839.46214 | FO22: 780.065 | FP22: 488.29926 | FQ22: 166.87205 | FR22: 1138.854 | FS22: 1185.3175 | FT22: 519.54985 | FU22: 864.73813 | FV22: 1121.5446 | FW22: 144.96403 | FX22: =C22 -> 36.727325
A23: 8 | B23: Fuel Oil No. 6 | C23: 1936.8033 | D23: 2748.304 | E23: -811.50068 | F23: -0.29527326 | H23: 4942.4406 | I23: -2194.1366 | J23: -0.44393787 | L23: 350.78359 | M23: 323.88028 | N23: 362.65062 | O23: 374.76572 | P23: 352.1515 | Q23: 341.73773 | R23: 353.40061 | S23: 343.9081 | T23: 413.05171 | U23: 429.94554 | V23: 411.56689 | W23: 379.67117 | X23: 363.74345 | Y23: 399.5711 | Z23: 410.69853 | AA23: 367.71556 | AB23: 388.8752 | AC23: 386.80594 | AD23: 379.64433 | AE23: 400.93661 | AF23: 403.33062 | AG23: 395.04206 | AH23: 333.20859 | AI23: 353.05326 | AJ23: 303.49867 | AK23: 265.22296 | AL23: 310.70943 | AM23: 308.57337 | AN23: 301.56957 | AO23: 298.63427 | AP23: 299.61291 | AQ23: 294.88911 | AR23: 271.16827 | AS23: 302.95638 | AT23: 254.18468 | AU23: 255.18441 | AV23: 344.212 | AW23: 322.851 | AX23: 325.654 | AY23: 282.18 | AZ23: 309.958 | BA23: 384.888 | BB23: 438.638 | BC23: 385.205 | BD23: 373.813 | BE23: 396.312 | BF23: 303.595 | BG23: 287.054 | BH23: 310.82061 | BI23: 302.92979 | BJ23: 336.94588 | BK23: 335.48859 | BL23: 363.84667 | BM23: 317.61157 | BN23: 321.3435 | BO23: 337.03599 | BP23: 359.42483 | BQ23: 392.49383 | BR23: 367.25154 | BS23: 292.54341 | BT23: 278.15223 | BU23: 292.37712 | BV23: 335.0994 | BW23: 385.52346 | BX23: 392.47756 | BY23: 425.58038 | BZ23: 460.92713 | CA23: 425.72665 | CB23: 413.72851 | CC23: 464.65458 | CD23: 429.75017 | CE23: 410.04205 | CF23: 451.96223 | CG23: 437.3327 | CH23: 441.55313 | CI23: 445.25532 | CJ23: 455.07104 | CK23: 444.42504 | CL23: 481.80263 | CM23: 484.22615 | CN23: 451.80125 | CO23: 466.08447 | CP23: 397.6536 | CQ23: 386.50684 | CR23: 392.42822 | CS23: 416.76768 | CT23: 450.4208 | CU23: 463.27923 | CV23: 431.78022 | CW23: 418.46669 | CX23: 489.34877 | CY23: 425.3752 | CZ23: 445.10568 | DA23: 386.17858 | DB23: 318.44668 | DC23: 322.45613 | DD23: 386.84401 | DE23: 370.56154 | DF23: 386.2109 | DG23: 335.94046 | DH23: 348.72008 | DI23: 384.64831 | DJ23: 409.31223 | DK23: 396.09492 | DL23: 327.4078 | DM23: 357.38169 | DN23: 309.33473 | DO23: 331.65987 | DP23: 303.93967 | DQ23: 178.75508 | DR23: 383.07798 | DS23: 365.77175 | DT23: 396.03797 | DU23: 447.47332 | DV23: 458.596 | DW23: 439.55966 | DX23: 495.40542 | DY23: 464.69064 | DZ23: 475.66392 | EA23: 440.99517 | EB23: 440.12665 | EC23: 432.65736 | ED23: 485.29601 | EE23: 465.78942 | EF23: 491.88904 | EG23: 499.97522 | EH23: 446.04783 | EI23: 464.75177 | EJ23: 426.84401 | EK23: 395.68583 | EL23: 393.37743 | EM23: 274.64937 | EN23: 209.19729 | EO23: 271.90376 | EP23: 253.07552 | EQ23: 307.47065 | ER23: 249.70765 | ES23: 334.92533 | ET23: 344.95673 | EU23: 242.12378 | EV23: 285.95504 | EW23: 154.71055 | EX23: 94.27769 | EY23: 63.810874 | EZ23: 190.33825 | FA23: 135.33866 | FB23: 129.04635 | FC23: 137.49087 | FD23: 136.79926 | FE23: 145.684 | FF23: 149.1743 | FG23: 210.3626 | FH23: 280.60627 | FI23: 208.98488 | FJ23: 212.97789 | FL23: 4437.5135 | FM23: 4582.6253 | FN23: 3466.204 | FO23: 4154.36 | FP23: 4037.7362 | FQ23: 4714.0392 | FR23: 5343.6744 | FS23: 4960.0539 | FT23: 4344.1165 | FU23: 4849.9666 | FV23: 5217.0899 | FW23: 2812.1149 | FX23: =C23 -> 1936.8033
A24: 2 | B24: Fuel Oil No. 2 y No. 6 | C24: 0 | D24: 0 | E24: 0 | F24: 0 | H24: 56.126183 | I24: -56.126183 | J24: -1 | L24: 83.0682 | M24: 50.0019 | N24: 49.1954 | O24: 49.8913 | P24: 68.6832 | Q24: 69.8186 | R24: 109.82223 | S24: 68.4282 | T24: 45.4605 | U24: 63.1767 | V24: 33.2797 | W24: 94.6292 | X24: 95.3245 | Y24: 62.544 | Z24: 51.028 | AA24: 70.643 | AB24: 91.4553 | AC24: 58.97048 | AD24: 102.41889 | AE24: 90.25118 | AF24: 92.5349 | AG24: 59.95863 | AH24: 10.4828 | AI24: 10.83424 | AJ24: 9.306468 | AK24: 68.804286 | AL24: 86.246476 | AM24: 78.170953 | AN24: 87.067728 | AO24: 77.597756 | AP24: 102.56818 | AQ24: 61.454001 | AR24: 70.907333 | AS24: 90.682832 | AT24: 85.066742 | AU24: 90.030096 | AV24: 0 | AW24: 0 | AX24: 0 | AY24: 0 | AZ24: 0 | BA24: 0 | BB24: 0 | BC24: 0 | BD24: 0 | BE24: 0 | BF24: 0 | BG24: 0 | BH24: 74.351966 | BI24: 40.003578 | BJ24: 76.374457 | BK24: 41.470119 | BL24: 39.576238 | BM24: 60.131153 | BN24: 49.890335 | BO24: 90.079164 | BP24: 43.844671 | BQ24: 0 | BR24: 0 | BS24: 3.3692434 | BT24: 21.241662 | BU24: 33.3214 | BV24: 25.972376 | BW24: 19.560898 | BX24: 3.1278106 | BY24: 0.99255569 | BZ24: 10.415251 | CA24: 52.756947 | CB24: 51.879535 | CC24: 66.283731 | CD24: 1.1990312 | CE24: 0 | CF24: 0 | CG24: 0 | CH24: 0 | CI24: 0 | CJ24: 0 | CK24: 0 | CL24: 0 | CM24: 0 | CN24: 0 | CO24: 0 | CP24: 0 | CQ24: 0 | CR24: 0 | CS24: 0 | CT24: 0 | CU24: 0 | CV24: 77.776426 | CW24: 35.66647 | CX24: 1.0340738 | CY24: 42.01041 | CZ24: 46.970788 | DA24: 16.911882 | DB24: 1.5018001 | DC24: 0 | DD24: 54.624969 | DE24: 55.170757 | DF24: 27.332137 | DG24: 3.6569148 | DH24: 8.7981806 | DI24: 17.007704 | DJ24: 9.1079808 | DK24: 4.9741239 | DL24: 9.0762404 | DM24: 8.0394426 | DN24: 10.897722 | DO24: 14.253539 | DP24: 0.71712712 | DQ24: 0 | DR24: 0.51210141 | DS24: 0 | DT24: 12.889012 | DU24: 9.2612037 | DV24: 9.6877081 | DW24: 3.4857809 | DX24: 23.260324 | DY24: 11.752284 | DZ24: 7.3505261 | EA24: 4.0603683 | EB24: 0 | EC24: 0 | ED24: 0 | EE24: 0 | EF24: 0 | EG24: 0 | EH24: 0 | EI24: 19.7984 | EJ24: 28.794464 | EK24: 6.817097 | EL24: 0.71622178 | EM24: 0 | EN24: 0 | EO24: 0 | EP24: 0 | EQ24: 0 | ER24: 0 | ES24: 0 | ET24: 0 | EU24: 0 | EV24: 0 | EW24: 0 | EX24: 0 | EY24: 0 | EZ24: 0 | FA24: 0 | FB24: 0 | FC24: 0 | FD24: 0 | FE24: 0 | FF24: 0 | FG24: 0 | FH24: 0 | FI24: 0 | FJ24: 0 | FL24: 785.45513 | FM24: 796.44592 | FN24: 907.90285 | FO24: 0 | FP24: 519.09093 | FQ24: 286.7512 | FR24: 0 | FS24: 221.87185 | FT24: 222.93971 | FU24: 82.976435 | FV24: 56.126183 | FW24: 0 | FX24: =C24 -> 0
A25: 3 | B25: Hidráulica | C25: 1360.9457 | D25: 1131.3957 | E25: 229.54996 | F25: 0.20289096 | H25: 951.38075 | I25: 180.01496 | J25: 0.18921442 | L25: 130.23221 | M25: 137.98387 | N25: 116.07044 | O25: 116.26517 | P25: 171.62094 | Q25: 153.22043 | R25: 110.65353 | S25: 133.95041 | T25: 121.05712 | U25: 106.75549 | V25: 83.09271 | W25: 85.03893 | X25: 77.39864 | Y25: 55.65104 | Z25: 52.87805 | AA25: 70.82568 | AB25: 95.07596 | AC25: 164.88049 | AD25: 173.8929 | AE25: 178.92579 | AF25: 123.99023 | AG25: 140.55911 | AH25: 169.55583 | AI25: 130.81903 | AJ25: 113.58413 | AK25: 88.86467 | AL25: 90.783889 | AM25: 74.025069 | AN25: 88.830467 | AO25: 153.4129 | AP25: 139.96757 | AQ25: 180.43355 | AR25: 163.602 | AS25: 170.6778 | AT25: 137.12559 | AU25: 103.07729 | AV25: 94.589 | AW25: 96.259 | AX25: 103.254 | AY25: 159.661 | AZ25: 218.773 | BA25: 140.244 | BB25: 127.082 | BC25: 142.113 | BD25: 158.866 | BE25: 165.587 | BF25: 191.521 | BG25: 173.632 | BH25: 134.0028 | BI25: 116.82077 | BJ25: 106.69588 | BK25: 110.8429 | BL25: 156.42082 | BM25: 188.37387 | BN25: 195.7858 | BO25: 152.54863 | BP25: 160.96753 | BQ25: 157.42438 | BR25: 140.93053 | BS25: 144.20138 | BT25: 141.6006 | BU25: 120.66734 | BV25: 117.3149 | BW25: 108.37085 | BX25: 127.36011 | BY25: 108.44908 | BZ25: 87.912204 | CA25: 91.594893 | CB25: 90.423149 | CC25: 89.405636 | CD25: 83.529873 | CE25: 92.542198 | CF25: 74.691174 | CG25: 80.648703 | CH25: 89.910697 | CI25: 81.945284 | CJ25: 68.794167 | CK25: 76.685451 | CL25: 64.150156 | CM25: 56.118765 | CN25: 79.870163 | CO25: 80.107912 | CP25: 89.928052 | CQ25: 91.583602 | CR25: 83.921165 | CS25: 71.554544 | CT25: 74.51204 | CU25: 70.894115 | CV25: 114.33526 | CW25: 134.23568 | CX25: 106.67368 | CY25: 111.18645 | CZ25: 106.15618 | DA25: 154.38719 | DB25: 250.63329 | DC25: 225.33145 | DD25: 200.95106 | DE25: 138.42852 | DF25: 181.76724 | DG25: 196.31608 | DH25: 280.08923 | DI25: 143.96606 | DJ25: 168.54435 | DK25: 162.5926 | DL25: 202.99936 | DM25: 201.77986 | DN25: 171.11175 | DO25: 127.28276 | DP25: 174.98016 | DQ25: 232.53817 | DR25: 166.8644 | DS25: 164.42573 | DT25: 178.23922 | DU25: 131.51928 | DV25: 128.6618 | DW25: 107.90352 | DX25: 108.98038 | DY25: 151.11585 | DZ25: 117.40662 | EA25: 98.661815 | EB25: 100.4857 | EC25: 80.776559 | ED25: 75.718697 | EE25: 68.585453 | EF25: 72.08614 | EG25: 103.1428 | EH25: 90.469519 | EI25: 89.648297 | EJ25: 94.367416 | EK25: 105.20085 | EL25: 70.899323 | EM25: 73.726707 | EN25: 102.53122 | EO25: 88.945251 | EP25: 136.07831 | EQ25: 93.249553 | ER25: 88.270199 | ES25: 86.964837 | ET25: 89.815669 | EU25: 105.96167 | EV25: 103.24492 | EW25: 111.4205 | EX25: 124.91358 | EY25: 113.24503 | EZ25: 107.8539 | FA25: 98.398546 | FB25: 132.37785 | FC25: 126.59792 | FD25: 121.46901 | FE25: 150.54212 | FF25: 134.81536 | FG25: 157.28518 | FH25: 105.40834 | FI25: 125.39299 | FJ25: 100.80446 | FL25: 1465.9413 | FM25: 1434.4527 | FN25: 1504.3849 | FO25: 1771.581 | FP25: 1765.0153 | FQ25: 1259.1708 | FR25: 934.43413 | FS25: 1503.821 | FT25: 2175.8289 | FU25: 1761.297 | FV25: 1025.1075 | FW25: 1244.6407 | FX25: =C25 -> 1360.9457
A26: 4 | B26: Eòlica | C26: 1102.2548 | D26: 1068.7121 | E26: 33.542628 | F26: 0.031386027 | H26: 709.51264 | I26: 359.19951 | J26: 0.50626232 | L26: 0 | M26: 0 | N26: 0 | O26: 0 | P26: 0 | Q26: 0 | R26: 0 | S26: 0 | T26: 0 | U26: 0 | V26: 0 | W26: 0 | X26: 0 | Y26: 0 | Z26: 0 | AA26: 0 | AB26: 0 | AC26: 0 | AD26: 0 | AE26: 0 | AF26: 0 | AG26: 0 | AH26: 0 | AI26: 0 | AJ26: 0 | AK26: 0 | AL26: 0 | AM26: 0 | AN26: 0 | AO26: 0 | AP26: 0 | AQ26: 0 | AR26: 0.29546457 | AS26: 3.4121442 | AT26: 2.923479 | AU26: 7.114331 | AV26: 8.895 | AW26: 7.734 | AX26: 11.226 | AY26: 6.132 | AZ26: 8.012 | BA26: 8.672 | BB26: 12.593 | BC26: 9.246 | BD26: 3.839 | BE26: 3.699 | BF26: 2.756 | BG26: 11.33 | BH26: 26.803041 | BI26: 18.144141 | BJ26: 14.612194 | BK26: 22.582782 | BL26: 19.309188 | BM26: 27.211582 | BN26: 24.908539 | BO26: 24.095206 | BP26: 8.8094064 | BQ26: 10.16221 | BR26: 13.024204 | BS26: 28.923755 | BT26: 29.164996 | BU26: 21.879548 | BV26: 15.366891 | BW26: 21.875993 | BX26: 19.167157 | BY26: 22.658939 | BZ26: 26.038107 | CA26: 21.243358 | CB26: 17.536231 | CC26: 6.6013368 | CD26: 16.47489 | CE26: 20.769954 | CF26: 20.492698 | CG26: 18.054796 | CH26: 27.895966 | CI26: 23.922806 | CJ26: 27.11038 | CK26: 29.647274 | CL26: 31.332084 | CM26: 23.638174 | CN26: 13.223016 | CO26: 10.533108 | CP26: 22.266187 | CQ26: 35.56955 | CR26: 13.110925 | CS26: 11.856603 | CT26: 23.873474 | CU26: 10.276707 | CV26: 23.248139 | CW26: 35.209494 | CX26: 51.16454 | CY26: 43.894802 | CZ26: 28.404466 | DA26: 13.194676 | DB26: 13.658519 | DC26: 44.700189 | DD26: 29.70239 | DE26: 23.49532 | DF26: 35.729444 | DG26: 34.665914 | DH26: 37.906679 | DI26: 46.38996 | DJ26: 42.313924 | DK26: 37.905582 | DL26: 14.439804 | DM26: 23.160141 | DN26: 18.474134 | DO26: 33.721683 | DP26: 43.537386 | DQ26: 52.461899 | DR26: 26.602419 | DS26: 28.808699 | DT26: 44.34002 | DU26: 39.627595 | DV26: 48.120897 | DW26: 47.515106 | DX26: 32.36587 | DY26: 21.520419 | DZ26: 33.351196 | EA26: 62.952055 | EB26: 50.274032 | EC26: 54.755651 | ED26: 46.370656 | EE26: 68.700644 | EF26: 62.250771 | EG26: 96.270253 | EH26: 104.97026 | EI26: 88.016458 | EJ26: 39.923458 | EK26: 52.243149 | EL26: 45.737307 | EM26: 79.462324 | EN26: 98.930214 | EO26: 122.93762 | EP26: 102.80052 | EQ26: 79.151087 | ER26: 83.86773 | ES26: 111.74959 | ET26: 121.47784 | EU26: 107.97561 | EV26: 60.334241 | EW26: 98.959183 | EX26: 80.528503 | EY26: 70.41316 | EZ26: 87.373533 | FA26: 137.59281 | FB26: 112.68462 | FC26: 90.568051 | FD26: 114.72891 | FE26: 131.39207 | FF26: 141.38366 | FG26: 112.62105 | FH26: 54.247033 | FI26: 57.245839 | FJ26: 62.417195 | FL26: 0 | FM26: 0 | FN26: 13.745419 | FO26: 94.134 | FP26: 238.58625 | FQ26: 238.7774 | FR26: 283.68604 | FS26: 312.59254 | FT26: 377.90497 | FU26: 481.20356 | FV26: 788.97496 | FW26: 1139.1253 | FX26: =C26 -> 1102.2548
A27: 5 | B27: Solar Fotovoltaica | C27: 436.27951 | D27: 282.15362 | E27: 154.12589 | F27: 0.54624813 | H27: 142.4369 | I27: 139.71672 | J27: 0.98090258 | L27: 0 | M27: 0 | N27: 0 | O27: 0 | P27: 0 | Q27: 0 | R27: 0 | S27: 0 | T27: 0 | U27: 0 | V27: 0 | W27: 0 | X27: 0 | Y27: 0 | Z27: 0 | AA27: 0 | AB27: 0 | AC27: 0 | AD27: 0 | AE27: 0 | AF27: 0 | AG27: 0 | AH27: 0 | AI27: 0 | AJ27: 0 | AK27: 0 | AL27: 0 | AM27: 0 | AN27: 0 | AO27: 0 | AP27: 0 | AQ27: 0 | AR27: 0 | AS27: 0 | AT27: 0 | AU27: 0 | AV27: 0 | AW27: 0 | AX27: 0 | AY27: 0 | AZ27: 0 | BA27: 0 | BB27: 0 | BC27: 0 | BD27: 0 | BE27: 0 | BF27: 0 | BG27: 0 | BH27: 0 | BI27: 0 | BJ27: 0 | BK27: 0 | BL27: 0 | BM27: 0 | BN27: 0 | BO27: 0 | BP27: 0 | BQ27: 0 | BR27: 0 | BS27: 0 | BT27: 0 | BU27: 0 | BV27: 0 | BW27: 0 | BX27: 0 | BY27: 0 | BZ27: 0 | CA27: 0 | CB27: 0 | CC27: 0 | CD27: 0 | CE27: 0 | CF27: 0 | CG27: 0 | CH27: 0 | CI27: 0 | CJ27: 0 | CK27: 0 | CL27: 0 | CM27: 0 | CN27: 0 | CO27: 0 | CP27: 0 | CQ27: 0 | CR27: 0 | CS27: 0 | CT27: 0 | CU27: 0 | CV27: 0 | CW27: 0.8886039 | CX27: 4.3159442 | CY27: 2.6374192 | CZ27: 4.4295869 | DA27: 3.9755566 | DB27: 3.3197459 | DC27: 3.8811678 | DD27: 4.3831554 | DE27: 3.8484085 | DF27: 4.6030536 | DG27: 3.9416782 | DH27: 4.359607 | DI27: 4.3676131 | DJ27: 2.3715978 | DK27: 4.5455884 | DL27: 4.0803576 | DM27: 3.7246003 | DN27: 3.191524 | DO27: 3.8486661 | DP27: 3.5109256 | DQ27: 4.0134723 | DR27: 4.8624644 | DS27: 4.3311473 | DT27: 4.003458 | DU27: 4.0092632 | DV27: 4.3923577 | DW27: 4.8940347 | DX27: 12.062164 | DY27: 12.098354 | DZ27: 11.264137 | EA27: 12.137123 | EB27: 12.207238 | EC27: 11.548647 | ED27: 13.754283 | EE27: 14.052738 | EF27: 13.29842 | EG27: 13.7018 | EH27: 14.078239 | EI27: 13.837808 | EJ27: 11.903919 | EK27: 12.807407 | EL27: 11.246401 | EM27: 17.121318 | EN27: 24.387507 | EO27: 24.621369 | EP27: 26.883936 | EQ27: 28.635536 | ER27: 27.275679 | ES27: 26.657298 | ET27: 26.021732 | EU27: 26.566674 | EV27: 24.948968 | EW27: 25.389778 | EX27: 20.765147 | EY27: 22.93504 | EZ27: 24.060011 | FA27: 24.784503 | FB27: 31.4 | FC27: 34.656031 | FD27: 35.527131 | FE27: 33.370676 | FF27: 41.957794 | FG27: 54.125785 | FH27: 56.91724 | FI27: 48.964299 | FJ27: 50.516042 | FL27: 0 | FM27: 0 | FN27: 0 | FO27: 0 | FP27: 0 | FQ27: 0 | FR27: 0 | FS27: 23.448025 | FT27: 47.26585 | FU27: 81.5789 | FV27: 159.55822 | FW27: 305.08866 | FX27: =C27 -> 436.27951
A28: 6 | B28: Biomasa | C28: 187.61447 | D28: 148.55412 | E28: 39.060357 | F28: 0.26293688 | H28: 188.12505 | I28: -39.570936 | J28: -0.21034378 | L28: 0 | M28: 0 | N28: 0 | O28: 0 | P28: 0 | Q28: 0 | R28: 0 | S28: 0 | T28: 0 | U28: 0 | V28: 0 | W28: 0 | X28: 0 | Y28: 0 | Z28: 0 | AA28: 0 | AB28: 0 | AC28: 0 | AD28: 0 | AE28: 0 | AF28: 0 | AG28: 0 | AH28: 0 | AI28: 0 | AJ28: 0 | AK28: 0 | AL28: 0 | AM28: 0 | AN28: 0 | AO28: 0 | AP28: 0 | AQ28: 0 | AR28: 0 | AS28: 0 | AT28: 0 | AU28: 0 | AV28: 0 | AW28: 0 | AX28: 0 | AY28: 0 | AZ28: 0 | BA28: 0 | BB28: 0 | BC28: 0 | BD28: 0 | BE28: 0 | BF28: 0 | BG28: 0 | BH28: 0 | BI28: 0 | BJ28: 0 | BK28: 0 | BL28: 0 | BM28: 0 | BN28: 0 | BO28: 0 | BP28: 0 | BQ28: 0 | BR28: 0 | BS28: 0 | BT28: 0 | BU28: 0 | BV28: 0 | BW28: 0 | BX28: 0 | BY28: 0 | BZ28: 0 | CA28: 0 | CB28: 0 | CC28: 0 | CD28: 0 | CE28: 0 | CF28: 0 | CG28: 0 | CH28: 0 | CI28: 0 | CJ28: 0 | CK28: 0 | CL28: 0 | CM28: 0 | CN28: 0 | CO28: 0 | CP28: 0 | CQ28: 0 | CR28: 0 | CS28: 0 | CT28: 0 | CU28: 0 | CV28: 0 | CW28: 0 | CX28: 0 | CY28: 0 | CZ28: 0 | DA28: 0 | DB28: 0 | DC28: 0 | DD28: 0 | DE28: 0.48064488 | DF28: 5.6078697 | DG28: 13.273094 | DH28: 14.323914 | DI28: 15.538634 | DJ28: 11.563382 | DK28: 17.269348 | DL28: 16.398167 | DM28: 19.462928 | DN28: 5.508479 | DO28: 17.619839 | DP28: 15.864917 | DQ28: 16.9479 | DR28: 18.814807 | DS28: 18.119347 | DT28: 18.75478 | DU28: 18.696759 | DV28: 18.932663 | DW28: 19.555351 | DX28: 18.797597 | DY28: 15.836182 | DZ28: 2.1520464 | EA28: 19.221745 | EB28: 19.391589 | EC28: 17.713523 | ED28: 19.656218 | EE28: 18.944397 | EF28: 14.351487 | EG28: 18.940445 | EH28: 19.577746 | EI28: 19.788247 | EJ28: 19.410469 | EK28: 20.350932 | EL28: 0 | EM28: 18.400172 | EN28: 19.709148 | EO28: 9.955167 | EP28: 6.1285904 | EQ28: 13.132301 | ER28: 13.950061 | ES28: 13.71693 | ET28: 14.180315 | EU28: 2.3334588 | EV28: 15.630411 | EW28: 20.127182 | EX28: 19.690554 | EY28: 19.1068 | EZ28: 17.750912 | FA28: 17.390953 | FB28: 19.302962 | FC28: 19.488174 | FD28: 19.945185 | FE28: 18.942358 | FF28: 18.720552 | FG28: 19.554684 | FH28: 16.708736 | FI28: 13.33142 | FJ28: 6.4785384 | FL28: 0 | FM28: 0 | FN28: 0 | FO28: 0 | FP28: 0 | FQ28: 0 | FR28: 0 | FS28: 0 | FT28: 137.0463 | FU28: 201.6941 | FV28: 206.52523 | FW28: 167.66092 | FX28: =C28 -> 187.61447
A29: 7 | B29: Total Renovable No Convencional | C29: 1726.1488 | D29: 1499.4199 | E29: 226.72887 | F29: 0.15121106 | H29: 1040.0746 | I29: 459.3453 | J29: 0.4416465 | L29: 0 | M29: 0 | N29: 0 | O29: 0 | P29: 0 | Q29: 0 | R29: 0 | S29: 0 | T29: 0 | U29: 0 | V29: 0 | W29: 0 | X29: 0 | Y29: 0 | Z29: 0 | AA29: 0 | AB29: 0 | AC29: 0 | AD29: 0 | AE29: 0 | AF29: 0 | AG29: 0 | AH29: 0 | AI29: 0 | AJ29: 0 | AK29: 0 | AL29: 0 | AM29: 0 | AN29: 0 | AO29: 0 | AP29: 0 | AQ29: 0 | AR29: 0.29546457 | AS29: 3.4121442 | AT29: 2.923479 | AU29: 7.114331 | AV29: 8.895 | AW29: 7.734 | AX29: 11.226 | AY29: 6.132 | AZ29: 8.012 | BA29: 8.672 | BB29: 12.593 | BC29: 9.246 | BD29: 3.839 | BE29: 3.699 | BF29: 2.756 | BG29: 11.33 | BH29: 26.803041 | BI29: 18.144141 | BJ29: 14.612194 | BK29: 22.582782 | BL29: 19.309188 | BM29: 27.211582 | BN29: 24.908539 | BO29: 24.095206 | BP29: 8.8094064 | BQ29: 10.16221 | BR29: 13.024204 | BS29: 28.923755 | BT29: 29.164996 | BU29: 21.879548 | BV29: 15.366891 | BW29: 21.875993 | BX29: 19.167157 | BY29: 22.658939 | BZ29: 26.038107 | CA29: 21.243358 | CB29: 17.536231 | CC29: 6.6013368 | CD29: 16.47489 | CE29: 20.769954 | CF29: 20.492698 | CG29: 18.054796 | CH29: 27.895966 | CI29: 23.922806 | CJ29: 27.11038 | CK29: 29.647274 | CL29: 31.332084 | CM29: 23.638174 | CN29: 13.223016 | CO29: 10.533108 | CP29: 22.266187 | CQ29: 35.56955 | CR29: 13.110925 | CS29: 11.856603 | CT29: 23.873474 | CU29: 10.276707 | CV29: 23.248139 | CW29: 36.098098 | CX29: 55.480485 | CY29: 46.532222 | CZ29: 32.834053 | DA29: 17.170232 | DB29: 16.978265 | DC29: 48.581357 | DD29: 34.085545 | DE29: 27.824373 | DF29: 45.940367 | DG29: 51.880686 | DH29: 56.5902 | DI29: 66.296207 | DJ29: 56.248903 | DK29: 59.720518 | DL29: 34.918329 | DM29: 46.347669 | DN29: 27.174137 | DO29: 55.190188 | DP29: 62.913229 | DQ29: 73.423271 | DR29: 50.27969 | DS29: 51.259193 | DT29: 67.098259 | DU29: 62.333617 | DV29: 71.445918 | DW29: 71.964491 | DX29: 63.225631 | DY29: 49.454955 | DZ29: 46.767379 | EA29: 94.310923 | EB29: 81.87286 | EC29: 84.017821 | ED29: 79.781157 | EE29: 101.69778 | EF29: 89.900678 | EG29: 128.9125 | EH29: 138.62624 | EI29: 121.64251 | EJ29: 71.237845 | EK29: 85.401488 | EL29: 56.983708 | EM29: 114.98381 | EN29: 143.02687 | EO29: 157.51416 | EP29: 135.81305 | EQ29: 120.91892 | ER29: 125.09347 | ES29: 152.12382 | ET29: 161.67989 | EU29: 136.87574 | EV29: 100.91362 | EW29: 144.47614 | EX29: 120.9842 | EY29: 112.455 | EZ29: 129.18446 | FA29: 179.76827 | FB29: 163.38758 | FC29: 144.71226 | FD29: 170.20123 | FE29: 183.70511 | FF29: 202.06201 | FG29: 186.30152 | FH29: 127.87301 | FI29: 119.54156 | FJ29: 119.41178 | FL29: 0 | FM29: 0 | FN29: 13.745419 | FO29: 94.134 | FP29: 238.58625 | FQ29: 238.7774 | FR29: 283.68604 | FS29: 336.04056 | FT29: 562.21712 | FU29: 764.47656 | FV29: 1155.0584 | FW29: 1611.8749 | FX29: =C29 -> 1726.1488
B31: Composición Generación de Energía por tipo de Combustible | E31: PP | I31: PP
